<?xml version="1.0"?>
<robot xmlns:xacro="http://www.ros.org/wiki/xacro"  name="rover">

    <material name="grey">
        <color rgba="0.2 0.2 0.2 1"/>
    </material>

    <material name="white">
        <color rgba="1 1 1 1"/>
    </material>

    <material name="orange">
        <color rgba="1 0.3 0.1 1"/>
    </material>

    <material name="blue">
        <color rgba="0 0 1 1"/>
    </material>

    <link name="world"></link>
    

    <joint name="world_to_base" type="prismatic">
        <origin xyz="0 0 1.11" rpy="0 0 0"/>
        <parent link="world"/>
        <child link="base"/>  
        <axis xyz="0 -1 0"/>
        <limit effort="0.1" lower="-3.1" upper="3.1" velocity="0.2"/>      
    </joint>

    <link name="base">
    <visual>
            <origin xyz="0 0 0" rpy="0 1.5698 0"/>
            <geometry>
                <cylinder length="1" radius="0.03" />
            </geometry>
            <material name="blue" />
    </visual>
    <collision>
            <origin xyz="0 0 0" rpy="0 1.5698 0"/>
            <geometry>
                <cylinder length="1" radius="0.03" />
            </geometry>
    </collision>
    <inertial>
            <origin xyz="0 0 0" rpy="0 1.5698 0"/>
            <mass value="12" />
            <inertia ixx="2.26" ixy="0.0" ixz="0.0" iyy="6.26" iyz="0.0" izz="8.5" />
    </inertial>     
    </link>

    <joint name="base_to_l1" type="revolute">
        <parent link="base" />
        <child link="l1" />
        <origin  rpy="1.571 1.571 0" xyz="0.5 0 0" />
        <axis xyz="0 -1 0"/>
        <limit effort="0.1" lower="-3.1" upper="3.1" velocity="0.2"/>
    </joint>
    
    <joint name="base_to_l2" type="revolute">
        <parent link="base" />
        <child link="l2" />
        <origin  rpy="1.571 1.571 0" xyz="-0.5 0 0" />
        <axis xyz="0 -1 0"/>
        <limit effort="0.1" lower="-3.1" upper="3.1" velocity="0.2"/>
    </joint>
    
    <link name="l1">
        <visual>
            <origin xyz="0 0 0" rpy="1.571 0 0"/>
            <geometry>
                <cylinder length="0.06" radius="0.05" />
            </geometry>
            <material name="orange" />
        </visual>
        <collision>
            <origin xyz="0 0 0" rpy="1.571 0 0"/>
            <geometry>
                <cylinder length="0.06" radius="0.05" />
            </geometry>
        </collision>
        <inertial>
            <origin xyz="0 0 0" rpy="0 1.5698 0"/>
            <mass value="12" />
            <inertia ixx="2.26" ixy="0.0" ixz="0.0" iyy="6.26" iyz="0.0" izz="8.5" />
    </inertial> 
    </link>
    
    <link name="l2">
        <visual>
            <origin xyz="0 0 0" rpy="1.57 0 0"/>
            <geometry>
                <cylinder length="0.06" radius="0.05" />
            </geometry>
            <material name="orange" />
        </visual>
        <collision>
            <origin xyz="0 0 0" rpy="1.57 0 0"/>
            <geometry>
                <cylinder length="0.06" radius="0.05" />
            </geometry>
        </collision>
        <inertial>
            <origin xyz="0 0 0" rpy="0 1.5698 0"/>
            <mass value="12" />
            <inertia ixx="2.26" ixy="0.0" ixz="0.0" iyy="6.26" iyz="0.0" izz="8.5" />
    </inertial> 
    </link>
    
    <joint name="l1_to_l1_left1" type="fixed">
        <parent link="l1" />
        <child link="l1_left1" />
        <origin  rpy="0 0 0" xyz="0.3 0 0.8" />
        <axis xyz="0 -1 0"/>
        <limit effort="0.1" lower="-3.1" upper="3.1" velocity="0.2"/>
    </joint>
    
    <joint name="l1_to_l1_right1" type="fixed">
        <parent link="l1" />
        <child link="l1_right1" />
        <origin  rpy="0 0 0" xyz="0.3 0 -0.8" />
        <axis xyz="0 -1 0"/>
        <limit effort="0.1" lower="-3.1" upper="3.1" velocity="0.2"/>   
    </joint>
    
    <link name="l1_left1">
        <visual>
            <origin xyz="-0.14 0 -0.39" rpy="0 0.36 0"/>
            <geometry>
                <cylinder length="0.86" radius="0.03" />
            </geometry>
            <material name="orange" />
        </visual>
        <collision>
            <origin xyz="-0.14 0 -0.39" rpy="0 0.36 0"/>
            <geometry>
                <cylinder length="0.86" radius="0.03" />
            </geometry>
        </collision>
        <inertial>
            <origin xyz="0 0 0" rpy="0 1.5698 0"/>
            <mass value="12" />
            <inertia ixx="2.26" ixy="0.0" ixz="0.0" iyy="6.26" iyz="0.0" izz="8.5" />
    </inertial> 
    </link>
    
    <link name="l1_right1">
        <visual>
            <origin xyz="-0.14 0 0.39" rpy="0 -0.36 0"/>
            <geometry>
                <cylinder length="0.86" radius="0.03" />
            </geometry>
            <material name="orange" />
        </visual>
        <collision>
           <origin xyz="-0.14 0 0.39" rpy="0 -0.36 0"/>
            <geometry>
                <cylinder length="0.86" radius="0.03" />
            </geometry>
        </collision>
        <inertial>
            <origin xyz="0 0 0" rpy="0 1.5698 0"/>
            <mass value="12" />
            <inertia ixx="2.26" ixy="0.0" ixz="0.0" iyy="6.26" iyz="0.0" izz="8.5" />
    </inertial> 
    </link>
    
    <joint name="l1_left1_to_l1_left2" type="fixed">
        <parent link="l1_left1" />
        <child link="l1_left2" />
        <origin  rpy="0 0 0" xyz="0.5 0 0" />
        <axis xyz="0 -1 0"/>
        <limit effort="0.1" lower="-3.1" upper="3.1" velocity="0.2"/>
    </joint>
    
    <joint name="l1_right1_to_l1_right2" type="fixed">
        <parent link="l1_right1" />
        <child link="l1_right2" />
        <origin  rpy="0 0 0" xyz="0.5 0 0" />
        <axis xyz="0 -1 0"/>
        <limit effort="0.1" lower="-3.1" upper="3.1" velocity="0.2"/>
    </joint>
    
    <link name="l1_left2">
        <visual>
            <origin xyz="-0.23 0 0" rpy="0 1.57 0"/>
            <geometry>
                <cylinder length="0.55" radius="0.03" />
            </geometry>
            <material name="orange" />
        </visual>
        <collision>
           <origin xyz="-0.23 0 0" rpy="0 1.57 0"/>
            <geometry>
                <cylinder length="0.55" radius="0.03" />
            </geometry>
        </collision>
        <inertial>
            <origin xyz="0 0 0" rpy="0 1.5698 0"/>
            <mass value="12" />
            <inertia ixx="2.26" ixy="0.0" ixz="0.0" iyy="6.26" iyz="0.0" izz="8.5" />
    </inertial> 
    </link>
    
    <link name="l1_right2">
        <visual>
            <origin xyz="-0.23 0 0" rpy="0 1.57 0"/>
            <geometry>
                <cylinder length="0.55" radius="0.03" />
            </geometry>
            <material name="orange" />
        </visual>
        <collision>
           <origin xyz="-0.23 0 0" rpy="0 1.57 0"/>
            <geometry>
                <cylinder length="0.55" radius="0.03" />
            </geometry>
        </collision>
        <inertial>
            <origin xyz="0 0 0" rpy="0 1.5698 0"/>
            <mass value="12" />
            <inertia ixx="2.26" ixy="0.0" ixz="0.0" iyy="6.26" iyz="0.0" izz="8.5" />
    </inertial> 
    </link>
    
    <joint name="l2_to_l2_left1" type="fixed">
        <parent link="l2" />
        <child link="l2_left1" />
        <origin  rpy="0 0 0" xyz="0.3 0 -0.8" />
        <axis xyz="0 -1 0"/>
        <limit effort="0.1" lower="-3.1" upper="3.1" velocity="0.2"/>
    </joint>
    
    <joint name="l2_to_l2_right1" type="fixed">
        <parent link="l2" />
        <child link="l2_right1" />
        <origin  rpy="0 0 0" xyz="0.3 0 0.8" />
        <axis xyz="0 -1 0"/>
        <limit effort="0.1" lower="-3.1" upper="3.1" velocity="0.2"/>   
    </joint>
    
    <link name="l2_left1">
        <visual>
            <origin xyz="-0.14 0 0.39" rpy="0 -0.36 0"/>
            <geometry>
                <cylinder length="0.86" radius="0.03" />
            </geometry>
            <material name="orange" />
        </visual>
        <collision>
           <origin xyz="-0.14 0 0.39" rpy="0 -0.36 0"/>
            <geometry>
                <cylinder length="0.86" radius="0.03" />
            </geometry>
        </collision>
        <inertial>
            <origin xyz="0 0 0" rpy="0 1.5698 0"/>
            <mass value="12" />
            <inertia ixx="2.26" ixy="0.0" ixz="0.0" iyy="6.26" iyz="0.0" izz="8.5" />
    </inertial> 
    </link>
    
    <link name="l2_right1">
        <visual>
            <origin xyz="-0.14 0 -0.39" rpy="0 0.36 0"/>
            <geometry>
                <cylinder length="0.86" radius="0.03" />
            </geometry>
            <material name="orange" />
        </visual>
        <collision>
           <origin xyz="-0.14 0 -0.39" rpy="0 0.36 0"/>
            <geometry>
                <cylinder length="0.86" radius="0.03" />
            </geometry>
        </collision>
        <inertial>
            <origin xyz="0 0 0" rpy="0 1.5698 0"/>
            <mass value="12" />
            <inertia ixx="2.26" ixy="0.0" ixz="0.0" iyy="6.26" iyz="0.0" izz="8.5" />
    </inertial> 
    </link>
    
    <joint name="l2_left1_to_l2_left2" type="fixed">
        <parent link="l2_left1" />
        <child link="l2_left2" />
        <origin  rpy="0 0 0" xyz="0.5 0 0" />
        <axis xyz="0 -1 0"/>
        <limit effort="0.1" lower="-3.1" upper="3.1" velocity="0.2"/>
    </joint>
    
    <joint name="l2_right1_to_l2_right2" type="fixed">
        <parent link="l2_right1" />
        <child link="l2_right2" />
        <origin  rpy="0 0 0" xyz="0.5 0 0" />
        <axis xyz="0 -1 0"/>
        <limit effort="0.1" lower="-3.1" upper="3.1" velocity="0.2"/>
    </joint>
    
    <link name="l2_left2">
        <visual>
            <origin xyz="-0.23 0 0" rpy="0 1.57 0"/>
            <geometry>
                <cylinder length="0.55" radius="0.03" />
            </geometry>
            <material name="orange" />
        </visual>
        <collision>
            <origin xyz="-0.23 0 0" rpy="0 1.57 0"/>
            <geometry>
                <cylinder length="0.55" radius="0.03" />
            </geometry>
        </collision>
        <inertial>
            <origin xyz="0 0 0" rpy="0 1.5698 0"/>
            <mass value="12" />
            <inertia ixx="2.26" ixy="0.0" ixz="0.0" iyy="6.26" iyz="0.0" izz="8.5" />
    </inertial> 
    </link>
    
    <link name="l2_right2">
        <visual>
            <origin xyz="-0.23 0 0" rpy="0 1.57 0"/>
            <geometry>
                <cylinder length="0.55" radius="0.03" />
            </geometry>
            <material name="orange" />
        </visual>
        <collision>
            <origin xyz="-0.23 0 0" rpy="0 1.57 0"/>
            <geometry>
                <cylinder length="0.55" radius="0.03" />
            </geometry>
        </collision>
        <inertial>
            <origin xyz="0 0 0" rpy="0 1.5698 0"/>
            <mass value="12" />
            <inertia ixx="2.26" ixy="0.0" ixz="0.0" iyy="6.26" iyz="0.0" izz="8.5" />
    </inertial> 
    </link>
    
    <joint name="l1_left2_to_l1_left_wheel" type="continuous">
        <parent link="l1_left2" />
        <child link="l1_left_wheel" />
        <origin  rpy="0 0 1.57" xyz="0.05 0 0" />
        <axis xyz="0 -1 0"/>
        <limit effort="0.1" lower="-3.1" upper="3.1" velocity="0.2"/>
    </joint>
    
    <joint name="l1_right2_to_l1_right_wheel" type="continuous">
        <parent link="l1_right2" />
        <child link="l1_right_wheel" />
        <origin  rpy="0 0 1.57" xyz="0.05 0 0" />
        <axis xyz="0 -1 0"/>
        <limit effort="0.1" lower="-3.1" upper="3.1" velocity="0.2"/>
    </joint>
    
    <link name="l1_left_wheel">
        <visual>
            <origin xyz="0 0 0" rpy="1.57 0 0"/>
            <geometry>
                <cylinder length="0.05" radius="0.06" />
            </geometry>
            <material name="white" />
        </visual>
        <collision>
            <origin xyz="0 0 0" rpy="1.57 0 0"/>
            <geometry>
                <cylinder length="0.05" radius="0.06" />
            </geometry>
        </collision>
        <inertial>
            <origin xyz="0 0 0" rpy="0 1.5698 0"/>
            <mass value="12" />
            <inertia ixx="2.26" ixy="0.0" ixz="0.0" iyy="6.26" iyz="0.0" izz="8.5" />
    </inertial> 
    </link>
    
    <link name="l1_right_wheel">
        <visual>
            <origin xyz="0 0 0" rpy="1.57 0 0"/>
            <geometry>
                <cylinder length="0.05" radius="0.06" />
            </geometry>
            <material name="white" />
        </visual>
        <collision>
            <origin xyz="0 0 0" rpy="1.57 0 0"/>
            <geometry>
                <cylinder length="0.05" radius="0.06" />
            </geometry>
        </collision>
        <inertial>
            <origin xyz="0 0 0" rpy="0 1.5698 0"/>
            <mass value="12" />
            <inertia ixx="2.26" ixy="0.0" ixz="0.0" iyy="6.26" iyz="0.0" izz="8.5" />
    </inertial> 
    </link>
    
    <joint name="l2_left2_to_l2_left_wheel" type="continuous">
        <parent link="l2_left2" />
        <child link="l2_left_wheel" />
        <origin  rpy="0 0 1.57" xyz="0.05 0 0" />
        <axis xyz="0 -1 0"/>
    </joint>
    
    <joint name="l2_right2_to_l2_right_wheel" type="continuous">
        <parent link="l2_right2" />
        <child link="l2_right_wheel" />
        <origin  rpy="0 0 1.57" xyz="0.05 0 0" />
        <axis xyz="0 -1 0"/>
    </joint>
    
    <link name="l2_left_wheel">
        <visual>
            <origin xyz="0 0 0" rpy="1.57 0 0"/>
            <geometry>
                <cylinder length="0.05" radius="0.06" />
            </geometry>
            <material name="white" />
        </visual>
        <collision>
            <origin xyz="0 0 0" rpy="1.57 0 0"/>
            <geometry>
                <cylinder length="0.05" radius="0.06" />
            </geometry>
        </collision>
        <inertial>
            <origin xyz="0 0 0" rpy="0 1.5698 0"/>
            <mass value="12" />
            <inertia ixx="2.26" ixy="0.0" ixz="0.0" iyy="6.26" iyz="0.0" izz="8.5" />
    </inertial> 
    </link>
    
    <link name="l2_right_wheel">
        <visual>
            <origin xyz="0 0 0" rpy="1.57 0 0"/>
            <geometry>
                <cylinder length="0.05" radius="0.06" />
            </geometry>
            <material name="white" />
        </visual>
        <collision>
            <origin xyz="0 0 0" rpy="1.57 0 0"/>
            <geometry>
                <cylinder length="0.05" radius="0.06" />
            </geometry>
        </collision>
        <inertial>
            <origin xyz="0 0 0" rpy="0 1.5698 0"/>
            <mass value="12" />
            <inertia ixx="2.26" ixy="0.0" ixz="0.0" iyy="6.26" iyz="0.0" izz="8.5" />
    </inertial> 
    </link>
    
    <joint name="l1_l_omni" type="fixed">
        <parent link="l1_left_wheel" />
        <child link="l1_l_omni" />
        <origin  rpy="0 0 0" xyz="0.05 0 0" />
        <axis xyz="0 -1 0"/>
    </joint>
    
    <joint name="l1_r_omni" type="fixed">
        <parent link="l1_right_wheel" />
        <child link="l1_r_omni" />
        <origin  rpy="0 0 0" xyz="0.05 0 0" />
        <axis xyz="0 -1 0"/>
    </joint>
    
    <link name="l1_l_omni">
        <visual>
            <origin xyz="0 -0.08 0" rpy="1.57 0 0"/>
            <geometry>
                <cylinder length="0.15" radius="0.01" />
            </geometry>
            <material name="white" />
        </visual>
        <collision>
            <origin xyz="0 -0.08 0" rpy="1.57 0 0"/>
            <geometry>
                <cylinder length="0.15" radius="0.01" />
            </geometry>
        </collision>
        <inertial>
            <origin xyz="0 0 0" rpy="0 1.5698 0"/>
            <mass value="12" />
            <inertia ixx="2.26" ixy="0.0" ixz="0.0" iyy="6.26" iyz="0.0" izz="8.5" />
    </inertial> 
    </link>
    
    <link name="l1_r_omni">
        <visual>
            <origin xyz="0 -0.08 0" rpy="1.57 0 0"/>
            <geometry>
                <cylinder length="0.15" radius="0.01" />
            </geometry>
            <material name="white" />
        </visual>
        <collision>
            <origin xyz="0 -0.08 0" rpy="1.57 0 0"/>
            <geometry>
                <cylinder length="0.15" radius="0.01" />
            </geometry>
        </collision>
        <inertial>
            <origin xyz="0 0 0" rpy="0 1.5698 0"/>
            <mass value="12" />
            <inertia ixx="2.26" ixy="0.0" ixz="0.0" iyy="6.26" iyz="0.0" izz="8.5" />
    </inertial> 
    </link>
    
    <joint name="l2_l_omni" type="fixed">
        <parent link="l2_left_wheel" />
        <child link="l2_l_omni" />
        <origin  rpy="0 0 0" xyz="0.05 0 0" />
        <axis xyz="0 -1 0"/>
    </joint>
    
    <joint name="l2_r_omni" type="fixed">
        <parent link="l2_right_wheel" />
        <child link="l2_r_omni" />
        <origin  rpy="0 0 0" xyz="0.05 0 0" />
        <axis xyz="0 -1 0"/>
    </joint>
    
    <link name="l2_l_omni">
        <visual>
            <origin xyz="0 -0.08 0" rpy="1.57 0 0"/>
            <geometry>
                <cylinder length="0.15" radius="0.01" />
            </geometry>
            <material name="white" />
        </visual>
        <collision>
            <origin xyz="0 -0.08 0" rpy="1.57 0 0"/>
            <geometry>
                <cylinder length="0.15" radius="0.01" />
            </geometry>
        </collision>
        <inertial>
            <origin xyz="0 0 0" rpy="0 1.5698 0"/>
            <mass value="12" />
            <inertia ixx="2.26" ixy="0.0" ixz="0.0" iyy="6.26" iyz="0.0" izz="8.5" />
    </inertial> 
    </link>
    
    <link name="l2_r_omni">
        <visual>
            <origin xyz="0 -0.08 0" rpy="1.57 0 0"/>
            <geometry>
                <cylinder length="0.15" radius="0.01" />
            </geometry>
            <material name="white" />
        </visual>
        <collision>
            <origin xyz="0 -0.08 0" rpy="1.57 0 0"/>
            <geometry>
                <cylinder length="0.15" radius="0.01" />
            </geometry>
        </collision>
        <inertial>
            <origin xyz="0 0 0" rpy="0 1.5698 0"/>
            <mass value="12" />
            <inertia ixx="2.26" ixy="0.0" ixz="0.0" iyy="6.26" iyz="0.0" izz="8.5" />
    </inertial> 
    </link>
    
    <joint name="l1_l_pivot" type="fixed">
        <parent link="l1_l_omni" />
        <child link="l1_l_pivot" />
        <origin  rpy="0 0 -1.57" xyz="0 -0.15 0" />
        <axis xyz="0 -1 0"/>
    </joint>
    
    <joint name="l1_r_pivot" type="fixed">
        <parent link="l1_r_omni" />
        <child link="l1_r_pivot" />
        <origin  rpy="0 0 -1.57" xyz="0 -0.15 0" />
        <axis xyz="0 -1 0"/>
    </joint>
    
    <link name="l1_l_pivot">
        <visual>
            <origin xyz="0 -0.02 0" rpy="1.57 0 0"/>
            <geometry>
                <cylinder length="0.03" radius="0.03" />
            </geometry>
            <material name="white" />
        </visual>
        <collision>
            <origin xyz="0 -0.02 0" rpy="1.57 0 0"/>
            <geometry>
                <cylinder length="0.03" radius="0.03" />
            </geometry>
        </collision>
        <inertial>
            <origin xyz="0 0 0" rpy="0 1.5698 0"/>
            <mass value="12" />
            <inertia ixx="2.26" ixy="0.0" ixz="0.0" iyy="6.26" iyz="0.0" izz="8.5" />
    </inertial> 
    </link>
    
    <link name="l1_r_pivot">
        <visual>
            <origin xyz="0 -0.02 0" rpy="1.57 0 0"/>
            <geometry>
                <cylinder length="0.03" radius="0.03" />
            </geometry>
            <material name="white" />
        </visual>
        <collision>
            <origin xyz="0 -0.02 0" rpy="1.57 0 0"/>
            <geometry>
                <cylinder length="0.03" radius="0.03" />
            </geometry>
        </collision>
        <inertial>
            <origin xyz="0 0 0" rpy="0 1.5698 0"/>
            <mass value="12" />
            <inertia ixx="2.26" ixy="0.0" ixz="0.0" iyy="6.26" iyz="0.0" izz="8.5" />
    </inertial> 
    </link>
    
    <joint name="l2_l_pivot" type="fixed">
        <parent link="l2_l_omni" />
        <child link="l2_l_pivot" />
        <origin  rpy="0 0 -1.57" xyz="0 -0.15 0" />
        <axis xyz="0 -1 0"/>
    </joint>
    
    <joint name="l2_r_pivot" type="fixed">
        <parent link="l2_r_omni" />
        <child link="l2_r_pivot" />
        <origin  rpy="0 0 -1.57" xyz="0 -0.15 0" />
        <axis xyz="0 -1 0"/>
    </joint>
    
    <link name="l2_l_pivot">
        <visual>
            <origin xyz="0 -0.02 0" rpy="1.57 0 0"/>
            <geometry>
                <cylinder length="0.03" radius="0.03" />
            </geometry>
            <material name="white" />
        </visual>
        <collision>
            <origin xyz="0 -0.02 0" rpy="1.57 0 0"/>
            <geometry>
                <cylinder length="0.03" radius="0.03" />
            </geometry>
        </collision>
        <inertial>
            <origin xyz="0 0 0" rpy="0 1.5698 0"/>
            <mass value="12" />
            <inertia ixx="2.26" ixy="0.0" ixz="0.0" iyy="6.26" iyz="0.0" izz="8.5" />
    </inertial> 
    </link>
    
    <link name="l2_r_pivot">
        <visual>
            <origin xyz="0 -0.02 0" rpy="1.57 0 0"/>
            <geometry>
                <cylinder length="0.03" radius="0.03" />
            </geometry>
            <material name="white" />
        </visual>
        <collision>
            <origin xyz="0 -0.02 0" rpy="1.57 0 0"/>
            <geometry>
                <cylinder length="0.03" radius="0.03" />
            </geometry>
        </collision>
        <inertial>
            <origin xyz="0 0 0" rpy="0 1.5698 0"/>
            <mass value="12" />
            <inertia ixx="2.26" ixy="0.0" ixz="0.0" iyy="6.26" iyz="0.0" izz="8.5" />
    </inertial> 
    </link>
    
    <joint name="l1_l_wheel" type="continuous">
        <parent link="l1_l_pivot" />
        <child link="l1_l_wheel" />
        <origin  rpy="0 0 0" xyz="0 -0.05 0" />
        <axis xyz="0 -1 0"/>
    </joint>
    
    <joint name="l1_r_wheel" type="continuous">
        <parent link="l1_r_pivot" />
        <child link="l1_r_wheel" />
        <origin  rpy="0 0 0" xyz="0 -0.05 0" />
        <axis xyz="0 -1 0"/>
    </joint>
    
    <link name="l1_l_wheel">
        <visual>
            <origin xyz="0 0 0" rpy="1.57 0 0"/>
            <geometry>
                <cylinder length="0.03" radius="0.12" />
            </geometry>
            <material name="grey" />
        </visual>
        <collision>
            <origin xyz="0 0 0" rpy="1.57 0 0"/>
            <geometry>
                <cylinder length="0.03" radius="0.12" />
            </geometry>
        </collision>
        <inertial>
            <origin xyz="0 0 0" rpy="0 1.5698 0"/>
            <mass value="12" />
            <inertia ixx="2.26" ixy="0.0" ixz="0.0" iyy="6.26" iyz="0.0" izz="8.5" />
    </inertial> 
    </link>
    
    <link name="l1_r_wheel">
        <visual>
            <origin xyz="0 0 0" rpy="1.57 0 0"/>
            <geometry>
                <cylinder length="0.03" radius="0.12" />
            </geometry>
            <material name="grey" />
        </visual>
        <collision>
            <origin xyz="0 0 0" rpy="1.57 0 0"/>
            <geometry>
                <cylinder length="0.03" radius="0.12" />
            </geometry>
        </collision>
        <inertial>
            <origin xyz="0 0 0" rpy="0 1.5698 0"/>
            <mass value="12" />
            <inertia ixx="2.26" ixy="0.0" ixz="0.0" iyy="6.26" iyz="0.0" izz="8.5" />
    </inertial> 
    </link>
    
    <joint name="l2_l_wheel" type="continuous">
        <parent link="l2_l_pivot" />
        <child link="l2_l_wheel" />
        <origin  rpy="0 0 0" xyz="0 -0.05 0" />
        <axis xyz="0 -1 0"/>
    </joint>
    
    <joint name="l2_r_wheel" type="continuous">
        <parent link="l2_r_pivot" />
        <child link="l2_r_wheel" />
        <origin  rpy="0 0 0" xyz="0 -0.05 0" />
        <axis xyz="0 -1 0"/>
    </joint>
    
    <link name="l2_l_wheel">
        <visual>
            <origin xyz="0 0 0" rpy="1.57 0 0"/>
            <geometry>
                <cylinder length="0.03" radius="0.12" />
            </geometry>
            <material name="grey" />
        </visual>
        <collision>
            <origin xyz="0 0 0" rpy="1.57 0 0"/>
            <geometry>
                <cylinder length="0.03" radius="0.12" />
            </geometry>
        </collision>
        <inertial>
            <origin xyz="0 0 0" rpy="0 1.5698 0"/>
            <mass value="12" />
            <inertia ixx="2.26" ixy="0.0" ixz="0.0" iyy="6.26" iyz="0.0" izz="8.5" />
    </inertial> 
    </link>
    
    <link name="l2_r_wheel">
        <visual>
            <origin xyz="0 0 0" rpy="1.57 0 0"/>
            <geometry>
                <cylinder length="0.03" radius="0.12" />
            </geometry>
            <material name="grey" />
        </visual>
        <collision>
            <origin xyz="0 0 0" rpy="1.57 0 0"/>
            <geometry>
                <cylinder length="0.03" radius="0.12" />
            </geometry>
        </collision>
        <inertial>
            <origin xyz="0 0 0" rpy="0 1.5698 0"/>
            <mass value="12" />
            <inertia ixx="2.26" ixy="0.0" ixz="0.0" iyy="6.26" iyz="0.0" izz="8.5" />
    </inertial> 
    </link>   
</robot>
